<?xml version="1.0"?>
<robot xmlns:xacro="http://ros.org/wiki/xacro" name="four_wheel_car">

  <!-- Properties -->
  <xacro:property name="wheel_radius" value="0.05"/>
  <xacro:property name="wheel_width" value="0.02"/>
  <xacro:property name="base_length" value="0.4"/>
  <xacro:property name="base_width" value="0.3"/>
  <xacro:property name="base_height" value="0.1"/>
  <xacro:property name="wheel_separation_length" value="0.3"/> 

  <!-- Add a dummy base_footprint link to avoid KDL warning -->
  <link name="base_footprint">
    <!-- This link has no physical representation, it's just for KDL -->
  </link>
  
  <!-- Connect base_footprint to base_link -->
  <joint name="base_footprint_joint" type="fixed">
    <parent link="base_footprint"/>
    <child link="base_link"/>
    <origin xyz="0 0 ${wheel_radius}" rpy="0 0 0"/>
  </joint>

  <!-- Base Link -->
  <link name="base_link">
    <visual>
      <geometry>
        <box size="${base_length} ${base_width} ${base_height}"/>
      </geometry>
      <material name="blue">
        <color rgba="0 0 1 1"/>
      </material>
    </visual>
    <collision>
      <geometry>
        <box size="${base_length} ${base_width} ${base_height}"/>
      </geometry>
    </collision>
    <inertial>
      <mass value="2.0"/>
      <inertia ixx="0.01" iyy="0.01" izz="0.01" ixy="0" ixz="0" iyz="0"/>
    </inertial>
  </link>

  <!-- Wheel Definitions -->
  <xacro:macro name="wheel" params="wheel_name">
    <link name="${wheel_name}">
      <visual>
        <geometry>
          <cylinder radius="${wheel_radius}" length="${wheel_width}"/>
        </geometry>
        <origin xyz="0 0 0" rpy="1.5708 0 0"/>
      </visual>
      <collision>
        <geometry>
          <cylinder radius="${wheel_radius}" length="${wheel_width}"/>
        </geometry>
        <origin xyz="0 0 0" rpy="1.5708 0 0"/>
      </collision>
      <inertial>
        <mass value="0.5"/>
        <inertia ixx="0.001" iyy="0.001" izz="0.001" ixy="0" ixz="0" iyz="0"/>
      </inertial>
    </link>
  </xacro:macro>

  <xacro:wheel wheel_name="rear_left_wheel"/>
  <xacro:wheel wheel_name="rear_right_wheel"/>
  <xacro:wheel wheel_name="front_left_wheel"/>
  <xacro:wheel wheel_name="front_right_wheel"/>

  <!-- Joints -->
  <xacro:macro name="wheel_joint" params="parent_link child_link joint_name x y z">
    <joint name="${joint_name}" type="continuous">
      <parent link="${parent_link}"/>
      <child link="${child_link}"/>
      <origin xyz="${x} ${y} ${z}" rpy="0 0 0"/>
      <axis xyz="0 1 0"/>
    </joint>
  </xacro:macro>

  <xacro:wheel_joint parent_link="base_link" child_link="rear_left_wheel" joint_name="rear_left_wheel_joint" x="-0.15" y="0.15" z="-0.05"/>
  <xacro:wheel_joint parent_link="base_link" child_link="rear_right_wheel" joint_name="rear_right_wheel_joint" x="-0.15" y="-0.15" z="-0.05"/>
  <xacro:wheel_joint parent_link="base_link" child_link="front_left_wheel" joint_name="front_left_wheel_joint" x="0.15" y="0.15" z="-0.05"/>
  <xacro:wheel_joint parent_link="base_link" child_link="front_right_wheel" joint_name="front_right_wheel_joint" x="0.15" y="-0.15" z="-0.05"/>

  <!-- Gazebo material colors -->
  <gazebo reference="base_link">
    <material>Gazebo/Blue</material>
  </gazebo>

  <gazebo reference="rear_left_wheel">
    <material>Gazebo/Black</material>
  </gazebo>

  <gazebo reference="rear_right_wheel">
    <material>Gazebo/Black</material>
  </gazebo>

  <gazebo reference="front_left_wheel">
    <material>Gazebo/Black</material>
  </gazebo>

  <gazebo reference="front_right_wheel">
    <material>Gazebo/Black</material>
  </gazebo>

  <!-- Diff Drive Plugin - UPDATED for ROS2 -->
  <gazebo>
    <plugin name="diff_drive_controller" filename="libgazebo_ros_diff_drive.so">
      <ros>
        <remapping>cmd_vel:=/cmd_vel</remapping>
      </ros>
      <left_joint>rear_left_wheel_joint</left_joint>
      <right_joint>rear_right_wheel_joint</right_joint>
      <wheel_separation>0.3</wheel_separation>
      <wheel_diameter>0.1</wheel_diameter>
      <max_wheel_torque>10</max_wheel_torque>
      <odometry_frame>odom</odometry_frame>
      <robot_base_frame>base_link</robot_base_frame>
    </plugin>
  </gazebo>


</robot>